{
 "cells": [
  {
   "cell_type": "code",
   "execution_count": 1,
   "id": "46f170d1",
   "metadata": {},
   "outputs": [],
   "source": [
    "import joblib\n",
    "import cv2"
   ]
  },
  {
   "cell_type": "code",
   "execution_count": 2,
   "id": "425e25af",
   "metadata": {},
   "outputs": [],
   "source": [
    "import numpy as np"
   ]
  },
  {
   "cell_type": "code",
   "execution_count": 32,
   "id": "28670290",
   "metadata": {},
   "outputs": [],
   "source": [
    "class Predict:\n",
    "    def __init__(self):\n",
    "        self.model = load_model('model_final2')\n",
    "        self.label = ['circle' , 'rectangle']\n",
    "    def predict(self , img_path):\n",
    "        img = cv2.imread(img_path)\n",
    "        print(img.shape)\n",
    "        ans = model.predict(img)\n",
    "        print(self.label(ans))"
   ]
  },
  {
   "cell_type": "code",
   "execution_count": 33,
   "id": "aa84b3b5",
   "metadata": {},
   "outputs": [],
   "source": [
    "pred = Predict()"
   ]
  },
  {
   "cell_type": "code",
   "execution_count": 34,
   "id": "38766ce9",
   "metadata": {},
   "outputs": [
    {
     "name": "stdout",
     "output_type": "stream",
     "text": [
      "(64, 64, 3)\n"
     ]
    },
    {
     "ename": "ValueError",
     "evalue": "in user code:\n\n    File \"C:\\Users\\marti\\anaconda3\\lib\\site-packages\\keras\\engine\\training.py\", line 1801, in predict_function  *\n        return step_function(self, iterator)\n    File \"C:\\Users\\marti\\anaconda3\\lib\\site-packages\\keras\\engine\\training.py\", line 1790, in step_function  **\n        outputs = model.distribute_strategy.run(run_step, args=(data,))\n    File \"C:\\Users\\marti\\anaconda3\\lib\\site-packages\\keras\\engine\\training.py\", line 1783, in run_step  **\n        outputs = model.predict_step(data)\n    File \"C:\\Users\\marti\\anaconda3\\lib\\site-packages\\keras\\engine\\training.py\", line 1751, in predict_step\n        return self(x, training=False)\n    File \"C:\\Users\\marti\\anaconda3\\lib\\site-packages\\keras\\utils\\traceback_utils.py\", line 67, in error_handler\n        raise e.with_traceback(filtered_tb) from None\n    File \"C:\\Users\\marti\\anaconda3\\lib\\site-packages\\keras\\engine\\input_spec.py\", line 264, in assert_input_compatibility\n        raise ValueError(f'Input {input_index} of layer \"{layer_name}\" is '\n\n    ValueError: Input 0 of layer \"sequential_6\" is incompatible with the layer: expected shape=(None, 64, 64, 3), found shape=(32, 64, 3)\n",
     "output_type": "error",
     "traceback": [
      "\u001b[1;31m---------------------------------------------------------------------------\u001b[0m",
      "\u001b[1;31mValueError\u001b[0m                                Traceback (most recent call last)",
      "\u001b[1;32m~\\AppData\\Local\\Temp/ipykernel_3856/2152002270.py\u001b[0m in \u001b[0;36m<module>\u001b[1;34m\u001b[0m\n\u001b[1;32m----> 1\u001b[1;33m \u001b[0mpred\u001b[0m\u001b[1;33m.\u001b[0m\u001b[0mpredict\u001b[0m\u001b[1;33m(\u001b[0m\u001b[1;34m'./toy_train/circle/101.jpg'\u001b[0m\u001b[1;33m)\u001b[0m\u001b[1;33m\u001b[0m\u001b[1;33m\u001b[0m\u001b[0m\n\u001b[0m",
      "\u001b[1;32m~\\AppData\\Local\\Temp/ipykernel_3856/3491380751.py\u001b[0m in \u001b[0;36mpredict\u001b[1;34m(self, img_path)\u001b[0m\n\u001b[0;32m      6\u001b[0m         \u001b[0mimg\u001b[0m \u001b[1;33m=\u001b[0m \u001b[0mcv2\u001b[0m\u001b[1;33m.\u001b[0m\u001b[0mimread\u001b[0m\u001b[1;33m(\u001b[0m\u001b[0mimg_path\u001b[0m\u001b[1;33m)\u001b[0m\u001b[1;33m\u001b[0m\u001b[1;33m\u001b[0m\u001b[0m\n\u001b[0;32m      7\u001b[0m         \u001b[0mprint\u001b[0m\u001b[1;33m(\u001b[0m\u001b[0mimg\u001b[0m\u001b[1;33m.\u001b[0m\u001b[0mshape\u001b[0m\u001b[1;33m)\u001b[0m\u001b[1;33m\u001b[0m\u001b[1;33m\u001b[0m\u001b[0m\n\u001b[1;32m----> 8\u001b[1;33m         \u001b[0mans\u001b[0m \u001b[1;33m=\u001b[0m \u001b[0mmodel\u001b[0m\u001b[1;33m.\u001b[0m\u001b[0mpredict\u001b[0m\u001b[1;33m(\u001b[0m\u001b[0mimg\u001b[0m\u001b[1;33m)\u001b[0m\u001b[1;33m\u001b[0m\u001b[1;33m\u001b[0m\u001b[0m\n\u001b[0m\u001b[0;32m      9\u001b[0m         \u001b[0mprint\u001b[0m\u001b[1;33m(\u001b[0m\u001b[0mself\u001b[0m\u001b[1;33m.\u001b[0m\u001b[0mlabel\u001b[0m\u001b[1;33m(\u001b[0m\u001b[0mans\u001b[0m\u001b[1;33m)\u001b[0m\u001b[1;33m)\u001b[0m\u001b[1;33m\u001b[0m\u001b[1;33m\u001b[0m\u001b[0m\n",
      "\u001b[1;32m~\\anaconda3\\lib\\site-packages\\keras\\utils\\traceback_utils.py\u001b[0m in \u001b[0;36merror_handler\u001b[1;34m(*args, **kwargs)\u001b[0m\n\u001b[0;32m     65\u001b[0m     \u001b[1;32mexcept\u001b[0m \u001b[0mException\u001b[0m \u001b[1;32mas\u001b[0m \u001b[0me\u001b[0m\u001b[1;33m:\u001b[0m  \u001b[1;31m# pylint: disable=broad-except\u001b[0m\u001b[1;33m\u001b[0m\u001b[1;33m\u001b[0m\u001b[0m\n\u001b[0;32m     66\u001b[0m       \u001b[0mfiltered_tb\u001b[0m \u001b[1;33m=\u001b[0m \u001b[0m_process_traceback_frames\u001b[0m\u001b[1;33m(\u001b[0m\u001b[0me\u001b[0m\u001b[1;33m.\u001b[0m\u001b[0m__traceback__\u001b[0m\u001b[1;33m)\u001b[0m\u001b[1;33m\u001b[0m\u001b[1;33m\u001b[0m\u001b[0m\n\u001b[1;32m---> 67\u001b[1;33m       \u001b[1;32mraise\u001b[0m \u001b[0me\u001b[0m\u001b[1;33m.\u001b[0m\u001b[0mwith_traceback\u001b[0m\u001b[1;33m(\u001b[0m\u001b[0mfiltered_tb\u001b[0m\u001b[1;33m)\u001b[0m \u001b[1;32mfrom\u001b[0m \u001b[1;32mNone\u001b[0m\u001b[1;33m\u001b[0m\u001b[1;33m\u001b[0m\u001b[0m\n\u001b[0m\u001b[0;32m     68\u001b[0m     \u001b[1;32mfinally\u001b[0m\u001b[1;33m:\u001b[0m\u001b[1;33m\u001b[0m\u001b[1;33m\u001b[0m\u001b[0m\n\u001b[0;32m     69\u001b[0m       \u001b[1;32mdel\u001b[0m \u001b[0mfiltered_tb\u001b[0m\u001b[1;33m\u001b[0m\u001b[1;33m\u001b[0m\u001b[0m\n",
      "\u001b[1;32m~\\anaconda3\\lib\\site-packages\\tensorflow\\python\\framework\\func_graph.py\u001b[0m in \u001b[0;36mautograph_handler\u001b[1;34m(*args, **kwargs)\u001b[0m\n\u001b[0;32m   1145\u001b[0m           \u001b[1;32mexcept\u001b[0m \u001b[0mException\u001b[0m \u001b[1;32mas\u001b[0m \u001b[0me\u001b[0m\u001b[1;33m:\u001b[0m  \u001b[1;31m# pylint:disable=broad-except\u001b[0m\u001b[1;33m\u001b[0m\u001b[1;33m\u001b[0m\u001b[0m\n\u001b[0;32m   1146\u001b[0m             \u001b[1;32mif\u001b[0m \u001b[0mhasattr\u001b[0m\u001b[1;33m(\u001b[0m\u001b[0me\u001b[0m\u001b[1;33m,\u001b[0m \u001b[1;34m\"ag_error_metadata\"\u001b[0m\u001b[1;33m)\u001b[0m\u001b[1;33m:\u001b[0m\u001b[1;33m\u001b[0m\u001b[1;33m\u001b[0m\u001b[0m\n\u001b[1;32m-> 1147\u001b[1;33m               \u001b[1;32mraise\u001b[0m \u001b[0me\u001b[0m\u001b[1;33m.\u001b[0m\u001b[0mag_error_metadata\u001b[0m\u001b[1;33m.\u001b[0m\u001b[0mto_exception\u001b[0m\u001b[1;33m(\u001b[0m\u001b[0me\u001b[0m\u001b[1;33m)\u001b[0m\u001b[1;33m\u001b[0m\u001b[1;33m\u001b[0m\u001b[0m\n\u001b[0m\u001b[0;32m   1148\u001b[0m             \u001b[1;32melse\u001b[0m\u001b[1;33m:\u001b[0m\u001b[1;33m\u001b[0m\u001b[1;33m\u001b[0m\u001b[0m\n\u001b[0;32m   1149\u001b[0m               \u001b[1;32mraise\u001b[0m\u001b[1;33m\u001b[0m\u001b[1;33m\u001b[0m\u001b[0m\n",
      "\u001b[1;31mValueError\u001b[0m: in user code:\n\n    File \"C:\\Users\\marti\\anaconda3\\lib\\site-packages\\keras\\engine\\training.py\", line 1801, in predict_function  *\n        return step_function(self, iterator)\n    File \"C:\\Users\\marti\\anaconda3\\lib\\site-packages\\keras\\engine\\training.py\", line 1790, in step_function  **\n        outputs = model.distribute_strategy.run(run_step, args=(data,))\n    File \"C:\\Users\\marti\\anaconda3\\lib\\site-packages\\keras\\engine\\training.py\", line 1783, in run_step  **\n        outputs = model.predict_step(data)\n    File \"C:\\Users\\marti\\anaconda3\\lib\\site-packages\\keras\\engine\\training.py\", line 1751, in predict_step\n        return self(x, training=False)\n    File \"C:\\Users\\marti\\anaconda3\\lib\\site-packages\\keras\\utils\\traceback_utils.py\", line 67, in error_handler\n        raise e.with_traceback(filtered_tb) from None\n    File \"C:\\Users\\marti\\anaconda3\\lib\\site-packages\\keras\\engine\\input_spec.py\", line 264, in assert_input_compatibility\n        raise ValueError(f'Input {input_index} of layer \"{layer_name}\" is '\n\n    ValueError: Input 0 of layer \"sequential_6\" is incompatible with the layer: expected shape=(None, 64, 64, 3), found shape=(32, 64, 3)\n"
     ]
    }
   ],
   "source": [
    "pred.predict('./toy_train/circle/101.jpg')"
   ]
  },
  {
   "cell_type": "code",
   "execution_count": 22,
   "id": "68134c56",
   "metadata": {},
   "outputs": [],
   "source": [
    "model = load_model('model_final2')"
   ]
  },
  {
   "cell_type": "code",
   "execution_count": null,
   "id": "3432a85e",
   "metadata": {},
   "outputs": [],
   "source": []
  }
 ],
 "metadata": {
  "kernelspec": {
   "display_name": "Python 3 (ipykernel)",
   "language": "python",
   "name": "python3"
  },
  "language_info": {
   "codemirror_mode": {
    "name": "ipython",
    "version": 3
   },
   "file_extension": ".py",
   "mimetype": "text/x-python",
   "name": "python",
   "nbconvert_exporter": "python",
   "pygments_lexer": "ipython3",
   "version": "3.9.7"
  }
 },
 "nbformat": 4,
 "nbformat_minor": 5
}
